<?xml version='1.0'?>

<robot name="rosrover" xmlns:xacro="http://www.ros.org/wiki/xacro">

  <gazebo reference="chassis">
    <material>Gazebo/Blue</material>
  </gazebo>

  <gazebo reference="left_front_wheel">
    <material>Gazebo/Black</material>
  </gazebo>

  <gazebo reference="right_front_wheel">
    <material>Gazebo/Black</material>
  </gazebo>

  <gazebo reference="left_back_wheel">
    <material>Gazebo/Black</material>
  </gazebo>

  <gazebo reference="right_back_wheel">
    <material>Gazebo/Black</material>
  </gazebo>

  <gazebo reference="camera">
    <material>Gazebo/Black</material>
  </gazebo>

  <gazebo reference="lidar">
    <material>Gazebo/Black</material>
  </gazebo>

  <xacro:include filename="$(find my_robot)/urdf/rosrover.gazebo" />

  <link name="robot_footprint"></link>
  <joint name="robot_footprint_joint" type="fixed">
    <origin xyz="0 0 0" rpy="0 0 0" />
    <parent link="robot_footprint"/>
    <child link="chassis" />
  </joint>

  <link name='chassis'>
  <pose>0 0 0 0 0 0</pose>
    <inertial>
      <mass value="1.0"/>
      <origin xyz="0 0 0.1" rpy=" 0 0 0"/>
      <inertia
          ixx="0.1" ixy="0" ixz="0"
          iyy="0.1" iyz="0"
          izz="0.1"
      />
    </inertial>
            <collision name='chassis_collision'>
      		<origin xyz="0 0 0.1" rpy=" 0 0 0"/>
              <geometry>
                <box size="0.3 0.2 0.2">
                </box>
              </geometry>
            </collision>

            <visual name='chassis_visual'>
      		<origin xyz="0 0 0.1" rpy=" 0 0 0"/>
              <geometry>
                <box size="0.3 0.2 0.2">
                </box>
          	  <!--mesh filename="package://my_robot/meshes/rosroverlowpoly-body.stl" scale="0.001 0.001 0.001" /-->      
              </geometry>
            </visual>
    </link>
    <link name="left_front_wheel" >

    <inertial>
      <mass value="2.0"/>
      <origin xyz="0 0 0" rpy="0 0 0"/>
      <inertia
          ixx="0.1" ixy="0" ixz="0"
          iyy="0.1" iyz="0"
          izz="0.1"
      />
    </inertial>

   	<collision name='left_front_wheel_collision'>
      		<origin xyz="0 0 0" rpy="1.5707 0 0"/>
      	<geometry>
        	<cylinder radius="0.04" length="0.05" />
      	</geometry>
    	</collision>

    	<visual name='left_front_wheel_visual'>
    		<origin xyz="0 0 0" rpy="1.5707 0 0"/>
      	<geometry>
        	<cylinder radius="0.04" length="0.05" />

      	</geometry>
    	</visual>
    </link>

	<joint type="continuous" name="left_front_wheel_hinge"> 
		<origin xyz="0.1 0.1 0" rpy="0 0 0"/> 
    		<child link="left_front_wheel"/> 
    		<parent link="chassis"/> 
    		<axis xyz="0 1 0" rpy="0 0 0"/> 
    		<limit effort="10000" velocity="1000"/> 
    		<dynamics damping="1.0" friction="1.0"/> 
  	</joint> 

    <link name="right_front_wheel" >

    <inertial>
      <mass value="2.0"/>
      <origin xyz="0 0 0" rpy="0 0 0"/>
      <inertia
          ixx="0.1" ixy="0" ixz="0"
          iyy="0.1" iyz="0"
          izz="0.1"
      />
    </inertial>
    	<collision name='right_front_wheel_collision'>
      		<origin xyz="0 0 0" rpy="1.5707 0 0"/>
      	<geometry>
        	<cylinder radius="0.04" length="0.05" />
      	</geometry>
    </collision>
    <visual name='right_front_wheel_visual'>
    		<origin xyz="0 0 0" rpy="1.5707 0 0"/>
      	<geometry>
        	<cylinder radius="0.04" length="0.05" />
      	</geometry>
    </visual>
	</link>
	<joint type="continuous" name="right_front_wheel_hinge"> 
		<origin xyz="0.1 -0.1 0" rpy="0 1.5707 0"/> 
    		<child link="right_front_wheel"/> 
    		<parent link="chassis"/> 
    		<axis xyz="0 1 0" rpy="0 0 0"/> 
    		<limit effort="10000" velocity="1000"/> 
    		<dynamics damping="1.0" friction="1.0"/> 
  	</joint> 



 <link name="left_back_wheel" >
    <inertial>
      <mass value="2.0"/>
      <origin xyz="0 0 0" rpy="0 0 0"/>
      <inertia
          ixx="0.1" ixy="0" ixz="0"
          iyy="0.1" iyz="0"
          izz="0.1"
      />
    </inertial>
    	<collision name='left_back_wheel_collision'>
      		<origin xyz="0 0 0" rpy="0 0 0"/>
      	<geometry>
        	<cylinder radius="0.04" length="0.05" />
      	</geometry>
    </collision>
    <visual name='left_back_wheel_visual'>
    		<origin xyz="0 0 0" rpy="0 0 0"/>
      	<geometry>
        	<cylinder radius="0.04" length="0.05" />
      	</geometry>
    </visual>
	</link>
	<joint type="continuous" name="left_back_wheel_hinge"> 
		<origin xyz="-0.1 0.1 0" rpy="1.5707 0 0"/> 
    		<child link="left_back_wheel"/> 
    		<parent link="chassis"/> 
    		<axis xyz="0 1 0" rpy="0 0 0"/> 
    		<limit effort="10000" velocity="1000"/> 
    		<dynamics damping="1.0" friction="1.0"/> 
  	</joint> 

    <link name="right_back_wheel" >

    <inertial>
      <mass value="2.0"/>
      <origin xyz="0 0 0" rpy="0 0 0"/>
      <inertia
          ixx="0.1" ixy="0" ixz="0"
          iyy="0.1" iyz="0"
          izz="0.1"
      />
    </inertial>
    	<collision name='right_back_wheel_collision'>
      		<origin xyz="0 0 0" rpy="0 0 0"/>
      	<geometry>
        	<cylinder radius="0.04" length="0.05" />
      	</geometry>
    </collision>
    <visual name='right_back_wheel_visual'>
    		<origin xyz="0 0 0" rpy="0 0 0"/>
      	<geometry>
        	<cylinder radius="0.04" length="0.05" />
      	</geometry>
    </visual>
	</link>
	<joint type="continuous" name="right_back_wheel_hinge"> 
		<origin xyz="-0.1 -0.1 0" rpy="1.5707 0 0"/> 
    		<child link="right_back_wheel"/> 
    		<parent link="chassis"/> 
    		<axis xyz="0 1 0" rpy="0 0 0"/> 
    		<limit effort="10000" velocity="1000"/> 
    		<dynamics damping="1.0" friction="1.0"/> 
  	</joint> 

 	  <link name='camera'>

    <inertial>
      <mass value="2.0"/>
      <origin xyz="0 0 0" rpy="0 0 0"/>
      <inertia
          ixx="0.1" ixy="0" ixz="0"
          iyy="0.1" iyz="0"
          izz="0.1"
      />
    </inertial>
            <pose>0 0 0 0 0 0</pose>
            <collision name='camera_collision'>
		<origin xyz="0 0 0" rpy="0 0 0"/> 
              <geometry>
                <box size="0.04 0.08 0.04">
                </box>
              </geometry>
            </collision>
            <visual name='camera_visual'>
		<origin xyz="0 0 0" rpy="0 0 0"/> 
              <geometry>
          	  <!--mesh filename="package://my_robot/meshes/rosroverlowpoly-camera.stl" scale="0.001 0.001 0.001"/-->      
                <box size="0.04 0.08 0.04">
		</box>

              </geometry>
            </visual>
          </link>

	<joint type="fixed" name="camera_joint"> 
		<origin xyz="0.12 0 0.30" rpy="0 0 0"/> 
    		<child link="camera"/> 
    		<parent link="chassis"/> 
    		<axis xyz="1 0 0" rpy="0 0 0"/> 
    		<limit effort="10000" velocity="1000"/> 
    		<dynamics damping="1.0" friction="1.0"/> 
  	</joint> 

 	  <link name='lidar'>
    <inertial>
      <mass value="2.0"/>
      <origin xyz="0 0 0" rpy="0 0 0"/>
      <inertia
          ixx="0.1" ixy="0" ixz="0"
          iyy="0.1" iyz="0"
          izz="0.1"
      />
    </inertial>
            <pose>-0 0 0 0 0 0</pose>
            <collision name='lidar_collision'>
    		<origin xyz="0 0 0" rpy="0 0 0"/>
              <geometry>
                <cylinder radius="0.02" length="0.100">
                </cylinder>
              </geometry>
            </collision>
            <visual name='lidar_visual'>
    		<origin xyz="0 0 0" rpy="0 0 0"/>
              <geometry>
		  <!--cylinder radius="0.02" length="0.100" /-->
          	  <mesh filename="package://my_robot/meshes/rosroverlowpoly-lidar.stl" scale=" 0.001 0.001 0.001"/>      
              </geometry>
            </visual>
          </link>
	<joint type="fixed" name="lidar_joint"> 
		<origin xyz="0 0.05 0.3" rpy="0 0 0"/> 
    		<child link="lidar"/> 
    		<parent link="chassis"/> 
    		<axis xyz="0 0 0 " rpy="0 0 0"/> 
    		<limit effort="10000" velocity="1000"/> 
    		<dynamics damping="1.0" friction="1.0"/> 
  	</joint> 
</robot>
